Workbook

Sheet Tong_Quan_Dashboard
A1: BÁO CÁO TỔNG QUAN PHẠM VI DỰ ÁN VIONE ECOSYSTEM (1,000+ WORK PACKAGES)
A3: Dữ liệu ước lượng tổng hợp từ 10 phân hệ nghiệp vụ doanh nghiệp chuẩn PMO Enterprise • Cập nhật: 2026-09-13
A5: TỔNG CÔNG VIỆC DỰ ÁN | C5: TIẾN ĐỘ TRUNG BÌNH | E5: TỔNG SỐ CHỨC NĂNG (TASKS)
A6: =SUM(D9:D18) | C6: =AVERAGE(E9:E18) | E6: =SUM(C9:C18)
A7: BẢNG PHÂN TÍCH TIẾN ĐỘ VÀ CÔNG VIỆC THEO 10 PHÂN HỆ CHUYÊN SÂU
A8: STT | B8: Tên Phân Hệ Nghiệp Vụ | C8: Số Chức Năng | D8: Công Việc (Man-days) | E8: Tiến Độ Trung Bình | F8: Trạng Thái Kiểm Thử | G8: Đánh Giá Nghiệm Thu
A9: 1 | B9: Tài Khoản, Phân Quyền RBAC & CRUD Toàn Hệ Thống | C9: =COUNTA(WBS_01_CORE_AUTH_CRUD!A5:A104) | D9: =SUM(WBS_01_CORE_AUTH_CRUD!L5:L104) | E9: =AVERAGE(WBS_01_CORE_AUTH_CRUD!M5:M104) | F9: Passed (100%) | G9: Đạt Chuẩn UAT
A10: 2 | B10: Tìm Kiếm, Phân Trang, Bộ Lọc & Chế Độ Màu Theme | C10: =COUNTA(WBS_02_SEARCH_PAGE_THEME!A5:A104) | D10: =SUM(WBS_02_SEARCH_PAGE_THEME!L5:L104) | E10: =AVERAGE(WBS_02_SEARCH_PAGE_THEME!M5:M104) | F10: Passed (100%) | G10: Đạt Chuẩn UAT
A11: 3 | B11: Mạng Lưới Kết Nối & Danh Bạ Doanh Nhân B2B | C11: =COUNTA(WBS_03_NETWORK_CONNECT!A5:A104) | D11: =SUM(WBS_03_NETWORK_CONNECT!L5:L104) | E11: =AVERAGE(WBS_03_NETWORK_CONNECT!M5:M104) | F11: Passed (100%) | G11: Đạt Chuẩn UAT
A12: 4 | B12: Bảng Tin Moments, Đa Phương Tiện & Cộng Đồng | C12: =COUNTA(WBS_04_MOMENTS_COMMUNITY!A5:A104) | D12: =SUM(WBS_04_MOMENTS_COMMUNITY!L5:L104) | E12: =AVERAGE(WBS_04_MOMENTS_COMMUNITY!M5:M104) | F12: Passed (100%) | G12: Đạt Chuẩn UAT
A13: 5 | B13: Nhắn Tin Realtime & Họp Trực Tuyến Video Call | C13: =COUNTA(WBS_05_CHAT_VIDEO_CALL!A5:A104) | D13: =SUM(WBS_05_CHAT_VIDEO_CALL!L5:L104) | E13: =AVERAGE(WBS_05_CHAT_VIDEO_CALL!M5:M104) | F13: Passed (100%) | G13: Đạt Chuẩn UAT
A14: 6 | B14: CRM Quản Trị Khách Hàng, Lead & Trao Cơ Hội Referral | C14: =COUNTA(WBS_06_CRM_LEADS_REFERRAL!A5:A104) | D14: =SUM(WBS_06_CRM_LEADS_REFERRAL!L5:L104) | E14: =AVERAGE(WBS_06_CRM_LEADS_REFERRAL!M5:M104) | F14: Passed (100%) | G14: Đạt Chuẩn UAT
A15: 7 | B15: Mẫu Email, Trình Soạn Thảo & Chiến Dịch Truyền Thông | C15: =COUNTA(WBS_07_EMAIL_TEMPLATES!A5:A104) | D15: =SUM(WBS_07_EMAIL_TEMPLATES!L5:L104) | E15: =AVERAGE(WBS_07_EMAIL_TEMPLATES!M5:M104) | F15: Passed (100%) | G15: Đạt Chuẩn UAT
A16: 8 | B16: Sàn Giao Thương B2B, Báo Giá RFQ & Hợp Đồng Điện Tử | C16: =COUNTA(WBS_08_B2B_MARKETPLACE!A5:A104) | D16: =SUM(WBS_08_B2B_MARKETPLACE!L5:L104) | E16: =AVERAGE(WBS_08_B2B_MARKETPLACE!M5:M104) | F16: Passed (100%) | G16: Đạt Chuẩn UAT
A17: 9 | B17: Tài Chính, Hóa Đơn VAT Điện Tử & Xử Lý Excel Hàng Loạt | C17: =COUNTA(WBS_09_FINANCE_VAT_EXCEL!A5:A104) | D17: =SUM(WBS_09_FINANCE_VAT_EXCEL!L5:L104) | E17: =AVERAGE(WBS_09_FINANCE_VAT_EXCEL!M5:M104) | F17: Passed (100%) | G17: Đạt Chuẩn UAT
A18: 10 | B18: Sự Kiện, Sơ Đồ Bàn Tiệc VIP, Bầu Cử Số & Thẻ NFC | C18: =COUNTA(WBS_10_EVENT_SEAT_VOTE!A5:A104) | D18: =SUM(WBS_10_EVENT_SEAT_VOTE!L5:L104) | E18: =AVERAGE(WBS_10_EVENT_SEAT_VOTE!M5:M104) | F18: Passed (100%) | G18: Đạt Chuẩn UAT
B19: TỔNG CỘNG TOÀN DỰ ÁN VIONE | C19: =SUM(C9:C18) | D19: =SUM(D9:D18) | E19: =AVERAGE(E9:E18) | F19: 100% ĐẠT CHUẨN | G19: SẴN SÀNG TRIỂN KHAI

Sheet WBS_01_CORE_AUTH_CRUD
A1: VIONE MASTER WBS: TÀI KHOẢN, PHÂN QUYỀN RBAC & CRUD TOÀN HỆ THỐNG
A3: Tài liệu phạm vi chi tiết PMO Enterprise: 100 tác vụ chuyên sâu • Cập nhật: 2026-09-13
A4: Mã WBS | B4: Phân Hệ | C4: Hạng Mục Cha (Epic / Phase) | D4: Chức Năng Con Chi Tiết (User Story / Work Package) | E4: Mô Tả Luồng Nghiệp Vụ & Xử Lý Kỹ Thuật (Chi Tiết Chuyên Gia) | F4: Tuyến Đường / Endpoint / Screen | G4: Vai Trò Thao Tác (Actor) | H4: Mức Độ Ưu Tiên | I4: Ước Lượng FE (Man-days) | J4: Ước Lượng BE (Man-days) | K4: Ước Lượng QA (Man-days) | L4: Tổng Công Việc (Man-days) | M4: Tiến Độ (%) | N4: Trạng Thái Dev | O4: Trạng Thái Kiểm Thử | P4: Trạng Thái Nghiệm Thu | Q4: Ghi Chú Kỹ Thuật & Kiến Trúc Vận Hành
A5: WBS-CORE-0001 | B5: Tài Khoản, Phân Quyền RBAC & CRUD Toàn Hệ Thống | C5: Tài Khoản & Quản Trị Hệ Thống [Giai đoạn: Khởi Tạo, Phân Tích Nghiệp Vụ & Mô Hình Dữ Liệu] | D5: [Kiến Trúc & Schema] Đăng ký tài khoản doanh nghiệp mới qua biểu mẫu chuẩn | E5: Phân tích yêu cầu nghiệp vụ, thiết kế bảng dữ liệu CSDL PostgreSQL, đặc tả API RESTful và luồng nghiệp vụ chi tiết cho: Validate MST, email, số điện thoại, kiểm tra trùng lặp pháp nhân trong CSDL | F5: /auth/register | G5: Khách Vãng Lai | H5: Cao | I5: 0.5 | J5: 1.5 | K5: 0.5 | L5: =SUM(I5:K5) | M5: 100 | N5: Hoàn thành Dev | O5: Passed | P5: Đạt UAT | Q5: NestJS DTO Validation
A6: WBS-CORE-0002 | B6: Tài Khoản, Phân Quyền RBAC & CRUD Toàn Hệ Thống | C6: Tài Khoản & Quản Trị Hệ Thống [Giai đoạn: Khởi Tạo, Phân Tích Nghiệp Vụ & Mô Hình Dữ Liệu] | D6: [Kiến Trúc & Schema] Đăng nhập tài khoản đa phương thức (Email, Mã hội viên, SĐT) | E6: Phân tích yêu cầu nghiệp vụ, thiết kế bảng dữ liệu CSDL PostgreSQL, đặc tả API RESTful và luồng nghiệp vụ chi tiết cho: Xác thực mật khẩu băm Argon2id/Bcrypt, cấp phát cặp JWT Token | F6: /auth/login | G6: Người Dùng | H6: Khẩn cấp | I6: 0.5 | J6: 1.5 | K6: 0.5 | L6: =SUM(I6:K6) | M6: 100 | N6: Hoàn thành Dev | O6: Passed | P6: Đạt UAT | Q6: JWT Access + Refresh Token
A7: WBS-CORE-0003 | B7: Tài Khoản, Phân Quyền RBAC & CRUD Toàn Hệ Thống | C7: Tài Khoản & Quản Trị Hệ Thống [Giai đoạn: Khởi Tạo, Phân Tích Nghiệp Vụ & Mô Hình Dữ Liệu] | D7: [Kiến Trúc & Schema] Đăng nhập sinh trắc học Passkey WebAuthn FIDO2 một chạm | E7: Phân tích yêu cầu nghiệp vụ, thiết kế bảng dữ liệu CSDL PostgreSQL, đặc tả API RESTful và luồng nghiệp vụ chi tiết cho: Đăng nhập một chạm qua vân tay/FaceID trên thiết bị hỗ trợ FIDO2 | F7: /auth/passkey | G7: Hội Viên | H7: Cao | I7: 0.5 | J7: 1.5 | K7: 0.5 | L7: =SUM(I7:K7) | M7: 100 | N7: Hoàn thành Dev | O7: Passed | P7: Đạt UAT | Q7: WebAuthn Standard
A8: WBS-CORE-0004 | B8: Tài Khoản, Phân Quyền RBAC & CRUD Toàn Hệ Thống | C8: Tài Khoản & Quản Trị Hệ Thống [Giai đoạn: Khởi Tạo, Phân Tích Nghiệp Vụ & Mô Hình Dữ Liệu] | D8: [Kiến Trúc & Schema] Đăng nhập 2 yếu tố TOTP (Google / Microsoft Authenticator) | E8: Phân tích yêu cầu nghiệp vụ, thiết kế bảng dữ liệu CSDL PostgreSQL, đặc tả API RESTful và luồng nghiệp vụ chi tiết cho: Bắt buộc nhập mã 6 số TOTP đối với tài khoản Ban Lãnh Đạo | F8: /auth/mfa-totp | G8: Ban Lãnh Đạo | H8: Khẩn cấp | I8: 0.5 | J8: 1.5 | K8: 0.5 | L8: =SUM(I8:K8) | M8: 100 | N8: Hoàn thành Dev | O8: Passed | P8: Đạt UAT | Q8: Otplib RFC 6238
A9: WBS-CORE-0005 | B9: Tài Khoản, Phân Quyền RBAC & CRUD Toàn Hệ Thống | C9: Tài Khoản & Quản Trị Hệ Thống [Giai đoạn: Khởi Tạo, Phân Tích Nghiệp Vụ & Mô Hình Dữ Liệu] | D9: [Kiến Trúc & Schema] Đăng xuất an toàn và vô hiệu hóa Token phiên làm việc | E9: Phân tích yêu cầu nghiệp vụ, thiết kế bảng dữ liệu CSDL PostgreSQL, đặc tả API RESTful và luồng nghiệp vụ chi tiết cho: Thu hồi Refresh Token trong Redis, xóa Cookie HttpOnly an toàn | F9: /auth/logout | G9: Người Dùng | H9: Cao | I9: 0.5 | J9: 1.5 | K9: 0.5 | L9: =SUM(I9:K9) | M9: 100 | N9: Hoàn thành Dev | O9: Passed | P9: Đạt UAT | Q9: Redis Token Revocation
A10: WBS-CORE-0006 | B10: Tài Khoản, Phân Quyền RBAC & CRUD Toàn Hệ Thống | C10: Tài Khoản & Quản Trị Hệ Thống [Giai đoạn: Khởi Tạo, Phân Tích Nghiệp Vụ & Mô Hình Dữ Liệu] | D10: [Kiến Trúc & Schema] Quên mật khẩu & Gửi link đặt lại mật khẩu qua Email | E10: Phân tích yêu cầu nghiệp vụ, thiết kế bảng dữ liệu CSDL PostgreSQL, đặc tả API RESTful và luồng nghiệp vụ chi tiết cho: Tạo token đặt lại có hạn 15 phút, gửi email chứa link một lần | F10: /auth/forgot-password | G10: Người Dùng | H10: Cao | I10: 0.5 | J10: 1.5 | K10: 0.5 | L10: =SUM(I10:K10) | M10: 100 | N10: Hoàn thành Dev | O10: Passed | P10: Đạt UAT | Q10: Crypto Random Bytes Token
A11: WBS-CORE-0007 | B11: Tài Khoản, Phân Quyền RBAC & CRUD Toàn Hệ Thống | C11: Tài Khoản & Quản Trị Hệ Thống [Giai đoạn: Khởi Tạo, Phân Tích Nghiệp Vụ & Mô Hình Dữ Liệu] | D11: [Kiến Trúc & Schema] Đổi mật khẩu người dùng từ màn hình cài đặt tài khoản | E11: Phân tích yêu cầu nghiệp vụ, thiết kế bảng dữ liệu CSDL PostgreSQL, đặc tả API RESTful và luồng nghiệp vụ chi tiết cho: Yêu cầu nhập mật khẩu cũ, kiểm tra độ mạnh mật khẩu chuẩn OWASP | F11: /settings/change-password | G11: Người Dùng | H11: Trung bình | I11: 0.5 | J11: 1.5 | K11: 0.5 | L11: =SUM(I11:K11) | M11: 100 | N11: Hoàn thành Dev | O11: Passed | P11: Đạt UAT | Q11: Password Strength Meter
A12: WBS-CORE-0008 | B12: Tài Khoản, Phân Quyền RBAC & CRUD Toàn Hệ Thống | C12: Tài Khoản & Quản Trị Hệ Thống [Giai đoạn: Khởi Tạo, Phân Tích Nghiệp Vụ & Mô Hình Dữ Liệu] | D12: [Kiến Trúc & Schema] Cập nhật thông tin hồ sơ cá nhân và chức danh hiệp hội | E12: Phân tích yêu cầu nghiệp vụ, thiết kế bảng dữ liệu CSDL PostgreSQL, đặc tả API RESTful và luồng nghiệp vụ chi tiết cho: Cập nhật họ tên, chức vụ doanh nghiệp, tiểu sử, ngành nghề hoạt động | F12: /profile/edit | G12: Hội Viên | H12: Cao | I12: 0.5 | J12: 1.5 | K12: 0.5 | L12: =SUM(I12:K12) | M12: 100 | N12: Hoàn thành Dev | O12: Passed | P12: Đạt UAT | Q12: Prisma Model Update
A13: WBS-CORE-0009 | B13: Tài Khoản, Phân Quyền RBAC & CRUD Toàn Hệ Thống | C13: Tài Khoản & Quản Trị Hệ Thống [Giai đoạn: Khởi Tạo, Phân Tích Nghiệp Vụ & Mô Hình Dữ Liệu] | D13: [Kiến Trúc & Schema] Tải lên ảnh đại diện Avatar và nén ảnh tự động phía Client | E13: Phân tích yêu cầu nghiệp vụ, thiết kế bảng dữ liệu CSDL PostgreSQL, đặc tả API RESTful và luồng nghiệp vụ chi tiết cho: Cắt ảnh tỷ lệ 1:1, nén dung lượng dưới 500KB trước khi upload | F13: /profile/avatar-upload | G13: Hội Viên | H13: Cao | I13: 0.5 | J13: 1.5 | K13: 0.5 | L13: =SUM(I13:K13) | M13: 100 | N13: Hoàn thành Dev | O13: Passed | P13: Đạt UAT | Q13: Canvas Image Compression
A14: WBS-CORE-0010 | B14: Tài Khoản, Phân Quyền RBAC & CRUD Toàn Hệ Thống | C14: Tài Khoản & Quản Trị Hệ Thống [Giai đoạn: Khởi Tạo, Phân Tích Nghiệp Vụ & Mô Hình Dữ Liệu] | D14: [Kiến Trúc & Schema] Tải lên ảnh bìa Cover Banner hồ sơ doanh nhân sắc nét | E14: Phân tích yêu cầu nghiệp vụ, thiết kế bảng dữ liệu CSDL PostgreSQL, đặc tả API RESTful và luồng nghiệp vụ chi tiết cho: Hỗ trợ ảnh panorama tỷ lệ 16:9, lưu trữ MinIO/S3 CDN tốc độ cao | F14: /profile/banner-upload | G14: Hội Viên | H14: Trung bình | I14: 0.5 | J14: 1.5 | K14: 0.5 | L14: =SUM(I14:K14) | M14: 100 | N14: Hoàn thành Dev | O14: Passed | P14: Đạt UAT | Q14: S3 Presigned URL Upload
A15: WBS-CORE-0011 | B15: Tài Khoản, Phân Quyền RBAC & CRUD Toàn Hệ Thống | C15: Tài Khoản & Quản Trị Hệ Thống [Giai đoạn: Khởi Tạo, Phân Tích Nghiệp Vụ & Mô Hình Dữ Liệu] | D15: [Kiến Trúc & Schema] Quản lý danh sách phiên đăng nhập và thiết bị đang kết nối | E15: Phân tích yêu cầu nghiệp vụ, thiết kế bảng dữ liệu CSDL PostgreSQL, đặc tả API RESTful và luồng nghiệp vụ chi tiết cho: Hiển thị IP, vị trí địa lý, trình duyệt, cho phép đăng xuất từ xa | F15: /settings/sessions | G15: Hội Viên | H15: Cao | I15: 0.5 | J15: 1.5 | K15: 0.5 | L15: =SUM(I15:K15) | M15: 100 | N15: Hoàn thành Dev | O15: Passed | P15: Đạt UAT | Q15: User Agent & IP Geolocation
A16: WBS-CORE-0012 | B16: Tài Khoản, Phân Quyền RBAC & CRUD Toàn Hệ Thống | C16: Tài Khoản & Quản Trị Hệ Thống [Giai đoạn: Khởi Tạo, Phân Tích Nghiệp Vụ & Mô Hình Dữ Liệu] | D16: [Kiến Trúc & Schema] Cơ chế Xóa Mềm (Soft Delete) bản ghi bảo toàn dữ liệu | E16: Phân tích yêu cầu nghiệp vụ, thiết kế bảng dữ liệu CSDL PostgreSQL, đặc tả API RESTful và luồng nghiệp vụ chi tiết cho: Gán cờ deleted_at = NOW(), ẩn bản ghi khỏi giao diện thông thường | F16: /api/crud/soft-delete | G16: Quản Trị Viên | H16: Khẩn cấp | I16: 0.5 | J16: 1.5 | K16: 0.5 | L16: =SUM(I16:K16) | M16: 100 | N16: Hoàn thành Dev | O16: Passed | P16: Đạt UAT | Q16: Prisma Soft Delete Middleware
... A104: WBS-CORE-0100 | B104: Tài Khoản, Phân Quyền RBAC & CRUD Toàn Hệ Thống | C104: Tài Khoản & Quản Trị Hệ Thống [Giai đoạn: Kiểm Thử Tự Động Toàn Diện E2E, Hiệu Năng & Nghiệm Thu UAT] | D104: [Kiểm Thử E2E & UAT] Chặn brute-force và khóa tài khoản tạm thời sau 5 lần sai pass | E104: Kiểm thử hộp đen/hộp trắng toàn diện, kiểm tra tải đồng thời, đối soát dữ liệu và nghiệm thu Ban Lãnh Đạo: Lưu số lần thử sai trong Redis với thời gian hết hạn TTL 15 phút | F104: /api/auth/rate-limit | G104: Hệ Thống Tự Động | H104: Khẩn cấp | I104: 0.5 | J104: 0.5 | K104: 2 | L104: =SUM(I104:K104) | M104: 100 | N104: Hoàn thành Dev | O104: Passed | P104: Đạt UAT | Q104: Redis Sliding Window Limiter
B105: TỔNG CỘNG PHÂN HỆ | I105: =SUM(I5:I104) | J105: =SUM(J5:J104) | K105: =SUM(K5:K104) | L105: =SUM(L5:L104) | M105: =AVERAGE(M5:M104)

Sheet WBS_02_SEARCH_PAGE_THEME
A1: VIONE MASTER WBS: TÌM KIẾM, PHÂN TRANG, BỘ LỌC & CHẾ ĐỘ MÀU THEME
A3: Tài liệu phạm vi chi tiết PMO Enterprise: 100 tác vụ chuyên sâu • Cập nhật: 2026-09-13
A4: Mã WBS | B4: Phân Hệ | C4: Hạng Mục Cha (Epic / Phase) | D4: Chức Năng Con Chi Tiết (User Story / Work Package) | E4: Mô Tả Luồng Nghiệp Vụ & Xử Lý Kỹ Thuật (Chi Tiết Chuyên Gia) | F4: Tuyến Đường / Endpoint / Screen | G4: Vai Trò Thao Tác (Actor) | H4: Mức Độ Ưu Tiên | I4: Ước Lượng FE (Man-days) | J4: Ước Lượng BE (Man-days) | K4: Ước Lượng QA (Man-days) | L4: Tổng Công Việc (Man-days) | M4: Tiến Độ (%) | N4: Trạng Thái Dev | O4: Trạng Thái Kiểm Thử | P4: Trạng Thái Nghiệm Thu | Q4: Ghi Chú Kỹ Thuật & Kiến Trúc Vận Hành
A5: WBS-SEARCH-0101 | B5: Tìm Kiếm, Phân Trang, Bộ Lọc & Chế Độ Màu Theme | C5: Tìm Kiếm & Giao Diện Người Dùng [Giai đoạn: Khởi Tạo, Phân Tích Nghiệp Vụ & Mô Hình Dữ Liệu] | D5: [Kiến Trúc & Schema] Tìm kiếm nhanh thời gian thực (Debounced Quick Search) | E5: Phân tích yêu cầu nghiệp vụ, thiết kế bảng dữ liệu CSDL PostgreSQL, đặc tả API RESTful và luồng nghiệp vụ chi tiết cho: Tự động gọi API sau 300ms dừng gõ phím, hiển thị kết quả gợi ý | F5: /search/quick | G5: Người Dùng | H5: Cao | I5: 0.5 | J5: 1.5 | K5: 0.5 | L5: =SUM(I5:K5) | M5: 100 | N5: Hoàn thành Dev | O5: Passed | P5: Đạt UAT | Q5: Custom useDebounce Hook
A6: WBS-SEARCH-0102 | B6: Tìm Kiếm, Phân Trang, Bộ Lọc & Chế Độ Màu Theme | C6: Tìm Kiếm & Giao Diện Người Dùng [Giai đoạn: Khởi Tạo, Phân Tích Nghiệp Vụ & Mô Hình Dữ Liệu] | D6: [Kiến Trúc & Schema] Tìm kiếm toàn văn tiếng Việt không dấu (Full-text Search) | E6: Phân tích yêu cầu nghiệp vụ, thiết kế bảng dữ liệu CSDL PostgreSQL, đặc tả API RESTful và luồng nghiệp vụ chi tiết cho: Hỗ trợ tìm kiếm danh bạ, tin tức, văn kiện bỏ qua dấu tiếng Việt | F6: /search/full-text | G6: Người Dùng | H6: Cao | I6: 0.5 | J6: 1.5 | K6: 0.5 | L6: =SUM(I6:K6) | M6: 100 | N6: Hoàn thành Dev | O6: Passed | P6: Đạt UAT | Q6: PostgreSQL unaccent & tsvector
A7: WBS-SEARCH-0103 | B7: Tìm Kiếm, Phân Trang, Bộ Lọc & Chế Độ Màu Theme | C7: Tìm Kiếm & Giao Diện Người Dùng [Giai đoạn: Khởi Tạo, Phân Tích Nghiệp Vụ & Mô Hình Dữ Liệu] | D7: [Kiến Trúc & Schema] Phân trang truyền thống (Offset Pagination) kèm chọn số dòng | E7: Phân tích yêu cầu nghiệp vụ, thiết kế bảng dữ liệu CSDL PostgreSQL, đặc tả API RESTful và luồng nghiệp vụ chi tiết cho: Hỗ trợ tùy chọn 10, 25, 50, 100 dòng mỗi trang, nhảy trang nhanh | F7: /components/pagination | G7: Người Dùng | H7: Cao | I7: 0.5 | J7: 1.5 | K7: 0.5 | L7: =SUM(I7:K7) | M7: 100 | N7: Hoàn thành Dev | O7: Passed | P7: Đạt UAT | Q7: Limit & Offset Optimization
A8: WBS-SEARCH-0104 | B8: Tìm Kiếm, Phân Trang, Bộ Lọc & Chế Độ Màu Theme | C8: Tìm Kiếm & Giao Diện Người Dùng [Giai đoạn: Khởi Tạo, Phân Tích Nghiệp Vụ & Mô Hình Dữ Liệu] | D8: [Kiến Trúc & Schema] Phân trang con trỏ (Cursor-based Pagination) cho Feed dữ liệu lớn | E8: Phân tích yêu cầu nghiệp vụ, thiết kế bảng dữ liệu CSDL PostgreSQL, đặc tả API RESTful và luồng nghiệp vụ chi tiết cho: Tối ưu hóa hiệu năng bảng tin hàng triệu bài viết, không bị lệch trang | F8: /api/feed/cursor | G8: Hệ Thống Tự Động | H8: Cao | I8: 0.5 | J8: 1.5 | K8: 0.5 | L8: =SUM(I8:K8) | M8: 100 | N8: Hoàn thành Dev | O8: Passed | P8: Đạt UAT | Q8: Indexed Cursor ID Paging
A9: WBS-SEARCH-0105 | B9: Tìm Kiếm, Phân Trang, Bộ Lọc & Chế Độ Màu Theme | C9: Tìm Kiếm & Giao Diện Người Dùng [Giai đoạn: Khởi Tạo, Phân Tích Nghiệp Vụ & Mô Hình Dữ Liệu] | D9: [Kiến Trúc & Schema] Cuộn vô tận (Infinite Scroll) tự động tải trang tiếp theo | E9: Phân tích yêu cầu nghiệp vụ, thiết kế bảng dữ liệu CSDL PostgreSQL, đặc tả API RESTful và luồng nghiệp vụ chi tiết cho: Sử dụng Intersection Observer API phát hiện đáy màn hình để fetch | F9: /components/infinite-scroll | G9: Người Dùng | H9: Cao | I9: 0.5 | J9: 1.5 | K9: 0.5 | L9: =SUM(I9:K9) | M9: 100 | N9: Hoàn thành Dev | O9: Passed | P9: Đạt UAT | Q9: IntersectionObserver API
A10: WBS-SEARCH-0106 | B10: Tìm Kiếm, Phân Trang, Bộ Lọc & Chế Độ Màu Theme | C10: Tìm Kiếm & Giao Diện Người Dùng [Giai đoạn: Khởi Tạo, Phân Tích Nghiệp Vụ & Mô Hình Dữ Liệu] | D10: [Kiến Trúc & Schema] Bộ lọc đa tiêu chí (Multi-criteria Faceted Filter) | E10: Phân tích yêu cầu nghiệp vụ, thiết kế bảng dữ liệu CSDL PostgreSQL, đặc tả API RESTful và luồng nghiệp vụ chi tiết cho: Lọc kết hợp: Ngành nghề + Khu vực + Hạng hội viên + Trạng thái phí | F10: /members/faceted-filter | G10: Ban Thư Ký | H10: Cao | I10: 0.5 | J10: 1.5 | K10: 0.5 | L10: =SUM(I10:K10) | M10: 100 | N10: Hoàn thành Dev | O10: Passed | P10: Đạt UAT | Q10: Prisma Dynamic Where Input
A11: WBS-SEARCH-0107 | B11: Tìm Kiếm, Phân Trang, Bộ Lọc & Chế Độ Màu Theme | C11: Tìm Kiếm & Giao Diện Người Dùng [Giai đoạn: Khởi Tạo, Phân Tích Nghiệp Vụ & Mô Hình Dữ Liệu] | D11: [Kiến Trúc & Schema] Lưu bộ lọc tìm kiếm ưa thích (Saved Custom Filters) | E11: Phân tích yêu cầu nghiệp vụ, thiết kế bảng dữ liệu CSDL PostgreSQL, đặc tả API RESTful và luồng nghiệp vụ chi tiết cho: Cho phép cán bộ quản lý lưu cấu hình bộ lọc để truy cập nhanh 1-click | F11: /filters/saved-views | G11: Quản Trị Viên | H11: Trung bình | I11: 0.5 | J11: 1.5 | K11: 0.5 | L11: =SUM(I11:K11) | M11: 100 | N11: Hoàn thành Dev | O11: Passed | P11: Đạt UAT | Q11: Local & Cloud Filter Sync
A12: WBS-SEARCH-0108 | B12: Tìm Kiếm, Phân Trang, Bộ Lọc & Chế Độ Màu Theme | C12: Tìm Kiếm & Giao Diện Người Dùng [Giai đoạn: Khởi Tạo, Phân Tích Nghiệp Vụ & Mô Hình Dữ Liệu] | D12: [Kiến Trúc & Schema] Sắp xếp cột linh hoạt đa cấp độ (Multi-column Sorting) | E12: Phân tích yêu cầu nghiệp vụ, thiết kế bảng dữ liệu CSDL PostgreSQL, đặc tả API RESTful và luồng nghiệp vụ chi tiết cho: Click tiêu đề cột để đảo chiều Tăng/Giảm (ASC/DESC), giữ trạng thái | F12: /components/data-table/sort | G12: Người Dùng | H12: Trung bình | I12: 0.5 | J12: 1.5 | K12: 0.5 | L12: =SUM(I12:K12) | M12: 100 | N12: Hoàn thành Dev | O12: Passed | P12: Đạt UAT | Q12: TanStack Table Sorting
A13: WBS-SEARCH-0109 | B13: Tìm Kiếm, Phân Trang, Bộ Lọc & Chế Độ Màu Theme | C13: Tìm Kiếm & Giao Diện Người Dùng [Giai đoạn: Khởi Tạo, Phân Tích Nghiệp Vụ & Mô Hình Dữ Liệu] | D13: [Kiến Trúc & Schema] Tùy biến hiển thị cột trong bảng dữ liệu (Column Visibility) | E13: Phân tích yêu cầu nghiệp vụ, thiết kế bảng dữ liệu CSDL PostgreSQL, đặc tả API RESTful và luồng nghiệp vụ chi tiết cho: Bật/tắt các cột dữ liệu tùy theo nhu cầu xem, lưu vào LocalStorage | F13: /components/data-table/columns | G13: Người Dùng | H13: Trung bình | I13: 0.5 | J13: 1.5 | K13: 0.5 | L13: =SUM(I13:K13) | M13: 100 | N13: Hoàn thành Dev | O13: Passed | P13: Đạt UAT | Q13: TanStack Table Visibility
A14: WBS-SEARCH-0110 | B14: Tìm Kiếm, Phân Trang, Bộ Lọc & Chế Độ Màu Theme | C14: Tìm Kiếm & Giao Diện Người Dùng [Giai đoạn: Khởi Tạo, Phân Tích Nghiệp Vụ & Mô Hình Dữ Liệu] | D14: [Kiến Trúc & Schema] Chế độ xem bảng dữ liệu Cô Đọng / Thoải Mái (Density Toggle) | E14: Phân tích yêu cầu nghiệp vụ, thiết kế bảng dữ liệu CSDL PostgreSQL, đặc tả API RESTful và luồng nghiệp vụ chi tiết cho: Chuyển đổi giữa Compact View (nhiều dữ liệu) và Comfortable View | F14: /components/data-table/density | G14: Người Dùng | H14: Thấp | I14: 0.5 | J14: 1.5 | K14: 0.5 | L14: =SUM(I14:K14) | M14: 100 | N14: Hoàn thành Dev | O14: Passed | P14: Đạt UAT | Q14: Tailwind Spacing Variables
A15: WBS-SEARCH-0111 | B15: Tìm Kiếm, Phân Trang, Bộ Lọc & Chế Độ Màu Theme | C15: Tìm Kiếm & Giao Diện Người Dùng [Giai đoạn: Khởi Tạo, Phân Tích Nghiệp Vụ & Mô Hình Dữ Liệu] | D15: [Kiến Trúc & Schema] Chế độ Sáng (Light Mode) chuẩn mực văn phòng trang nhã | E15: Phân tích yêu cầu nghiệp vụ, thiết kế bảng dữ liệu CSDL PostgreSQL, đặc tả API RESTful và luồng nghiệp vụ chi tiết cho: Màu nền trắng ngà dịu mắt, độ tương phản văn bản đạt chuẩn WCAG AA | F15: /theme/light | G15: Người Dùng | H15: Cao | I15: 0.5 | J15: 1.5 | K15: 0.5 | L15: =SUM(I15:K15) | M15: 100 | N15: Hoàn thành Dev | O15: Passed | P15: Đạt UAT | Q15: CSS Theme Token Variables
A16: WBS-SEARCH-0112 | B16: Tìm Kiếm, Phân Trang, Bộ Lọc & Chế Độ Màu Theme | C16: Tìm Kiếm & Giao Diện Người Dùng [Giai đoạn: Khởi Tạo, Phân Tích Nghiệp Vụ & Mô Hình Dữ Liệu] | D16: [Kiến Trúc & Schema] Chế độ Tối (Dark Mode) chuẩn doanh nhân sang trọng | E16: Phân tích yêu cầu nghiệp vụ, thiết kế bảng dữ liệu CSDL PostgreSQL, đặc tả API RESTful và luồng nghiệp vụ chi tiết cho: Nền đen tím sâu thẳm, giảm mỏi mắt ban đêm, tiết kiệm pin OLED | F16: /theme/dark | G16: Người Dùng | H16: Cao | I16: 0.5 | J16: 1.5 | K16: 0.5 | L16: =SUM(I16:K16) | M16: 100 | N16: Hoàn thành Dev | O16: Passed | P16: Đạt UAT | Q16: Tailwind dark: Variants
... A104: WBS-SEARCH-0200 | B104: Tìm Kiếm, Phân Trang, Bộ Lọc & Chế Độ Màu Theme | C104: Tìm Kiếm & Giao Diện Người Dùng [Giai đoạn: Kiểm Thử Tự Động Toàn Diện E2E, Hiệu Năng & Nghiệm Thu UAT] | D104: [Kiểm Thử E2E & UAT] Trang thông báo kết quả tìm kiếm rỗng (Empty State UX) | E104: Kiểm thử hộp đen/hộp trắng toàn diện, kiểm tra tải đồng thời, đối soát dữ liệu và nghiệm thu Ban Lãnh Đạo: Gợi ý từ khóa liên quan, nút xóa nhanh bộ lọc khi không có dữ liệu | F104: /components/empty-state | G104: Người Dùng | H104: Trung bình | I104: 0.5 | J104: 0.5 | K104: 2 | L104: =SUM(I104:K104) | M104: 100 | N104: Hoàn thành Dev | O104: Passed | P104: Đạt UAT | Q104: Illustrative Helpful Guidance
B105: TỔNG CỘNG PHÂN HỆ | I105: =SUM(I5:I104) | J105: =SUM(J5:J104) | K105: =SUM(K5:K104) | L105: =SUM(L5:L104) | M105: =AVERAGE(M5:M104)

Sheet WBS_03_NETWORK_CONNECT
A1: VIONE MASTER WBS: MẠNG LƯỚI KẾT NỐI & DANH BẠ DOANH NHÂN B2B
A3: Tài liệu phạm vi chi tiết PMO Enterprise: 100 tác vụ chuyên sâu • Cập nhật: 2026-09-13
A4: Mã WBS | B4: Phân Hệ | C4: Hạng Mục Cha (Epic / Phase) | D4: Chức Năng Con Chi Tiết (User Story / Work Package) | E4: Mô Tả Luồng Nghiệp Vụ & Xử Lý Kỹ Thuật (Chi Tiết Chuyên Gia) | F4: Tuyến Đường / Endpoint / Screen | G4: Vai Trò Thao Tác (Actor) | H4: Mức Độ Ưu Tiên | I4: Ước Lượng FE (Man-days) | J4: Ước Lượng BE (Man-days) | K4: Ước Lượng QA (Man-days) | L4: Tổng Công Việc (Man-days) | M4: Tiến Độ (%) | N4: Trạng Thái Dev | O4: Trạng Thái Kiểm Thử | P4: Trạng Thái Nghiệm Thu | Q4: Ghi Chú Kỹ Thuật & Kiến Trúc Vận Hành
A5: WBS-NETWORK-0201 | B5: Mạng Lưới Kết Nối & Danh Bạ Doanh Nhân B2B | C5: Mạng Lưới Doanh Nhân & Đối Tác [Giai đoạn: Khởi Tạo, Phân Tích Nghiệp Vụ & Mô Hình Dữ Liệu] | D5: [Kiến Trúc & Schema] Gửi lời mời kết nối kinh doanh (Send Connection Request) | E5: Phân tích yêu cầu nghiệp vụ, thiết kế bảng dữ liệu CSDL PostgreSQL, đặc tả API RESTful và luồng nghiệp vụ chi tiết cho: Kèm lời chào cá nhân hóa và mục tiêu hợp tác thương mại cụ thể | F5: /network/connect | G5: Hội Viên | H5: Khẩn cấp | I5: 0.5 | J5: 1.5 | K5: 0.5 | L5: =SUM(I5:K5) | M5: 100 | N5: Hoàn thành Dev | O5: Passed | P5: Đạt UAT | Q5: Business Connection Model
A6: WBS-NETWORK-0202 | B6: Mạng Lưới Kết Nối & Danh Bạ Doanh Nhân B2B | C6: Mạng Lưới Doanh Nhân & Đối Tác [Giai đoạn: Khởi Tạo, Phân Tích Nghiệp Vụ & Mô Hình Dữ Liệu] | D6: [Kiến Trúc & Schema] Hủy yêu cầu kết nối đã gửi khi chưa được chấp nhận | E6: Phân tích yêu cầu nghiệp vụ, thiết kế bảng dữ liệu CSDL PostgreSQL, đặc tả API RESTful và luồng nghiệp vụ chi tiết cho: Xóa lời mời khỏi hàng đợi đối tác, giải phóng trạng thái kết nối | F6: /network/cancel-request | G6: Hội Viên | H6: Trung bình | I6: 0.5 | J6: 1.5 | K6: 0.5 | L6: =SUM(I6:K6) | M6: 100 | N6: Hoàn thành Dev | O6: Passed | P6: Đạt UAT | Q6: Pending Status Revocation
A7: WBS-NETWORK-0203 | B7: Mạng Lưới Kết Nối & Danh Bạ Doanh Nhân B2B | C7: Mạng Lưới Doanh Nhân & Đối Tác [Giai đoạn: Khởi Tạo, Phân Tích Nghiệp Vụ & Mô Hình Dữ Liệu] | D7: [Kiến Trúc & Schema] Chấp nhận lời mời kết nối đối tác kinh doanh (Accept Connection) | E7: Phân tích yêu cầu nghiệp vụ, thiết kế bảng dữ liệu CSDL PostgreSQL, đặc tả API RESTful và luồng nghiệp vụ chi tiết cho: Kích hoạt quan hệ 2 chiều, mở quyền xem số điện thoại và nhắn tin | F7: /network/accept-request | G7: Hội Viên | H7: Khẩn cấp | I7: 0.5 | J7: 1.5 | K7: 0.5 | L7: =SUM(I7:K7) | M7: 100 | N7: Hoàn thành Dev | O7: Passed | P7: Đạt UAT | Q7: Mutual Access Authorization
A8: WBS-NETWORK-0204 | B8: Mạng Lưới Kết Nối & Danh Bạ Doanh Nhân B2B | C8: Mạng Lưới Doanh Nhân & Đối Tác [Giai đoạn: Khởi Tạo, Phân Tích Nghiệp Vụ & Mô Hình Dữ Liệu] | D8: [Kiến Trúc & Schema] Từ chối lời mời kết nối kèm thông báo lịch sự văn phong ngoại giao | E8: Phân tích yêu cầu nghiệp vụ, thiết kế bảng dữ liệu CSDL PostgreSQL, đặc tả API RESTful và luồng nghiệp vụ chi tiết cho: Chuyển trạng thái declined, không gửi thông báo tiêu cực cho đối phương | F8: /network/decline-request | G8: Hội Viên | H8: Trung bình | I8: 0.5 | J8: 1.5 | K8: 0.5 | L8: =SUM(I8:K8) | M8: 100 | N8: Hoàn thành Dev | O8: Passed | P8: Đạt UAT | Q8: Silent Decline Architecture
A9: WBS-NETWORK-0205 | B9: Mạng Lưới Kết Nối & Danh Bạ Doanh Nhân B2B | C9: Mạng Lưới Doanh Nhân & Đối Tác [Giai đoạn: Khởi Tạo, Phân Tích Nghiệp Vụ & Mô Hình Dữ Liệu] | D9: [Kiến Trúc & Schema] Hủy kết nối đối tác khi không còn nhu cầu giao thương (Remove) | E9: Phân tích yêu cầu nghiệp vụ, thiết kế bảng dữ liệu CSDL PostgreSQL, đặc tả API RESTful và luồng nghiệp vụ chi tiết cho: Thu hồi quyền xem số điện thoại cá nhân, giữ lại lịch sử giao dịch | F9: /network/disconnect | G9: Hội Viên | H9: Cao | I9: 0.5 | J9: 1.5 | K9: 0.5 | L9: =SUM(I9:K9) | M9: 100 | N9: Hoàn thành Dev | O9: Passed | P9: Đạt UAT | Q9: Relationship Dissolution
A10: WBS-NETWORK-0206 | B10: Mạng Lưới Kết Nối & Danh Bạ Doanh Nhân B2B | C10: Mạng Lưới Doanh Nhân & Đối Tác [Giai đoạn: Khởi Tạo, Phân Tích Nghiệp Vụ & Mô Hình Dữ Liệu] | D10: [Kiến Trúc & Schema] Chặn người dùng (Block User) khi có hành vi spam thương mại | E10: Phân tích yêu cầu nghiệp vụ, thiết kế bảng dữ liệu CSDL PostgreSQL, đặc tả API RESTful và luồng nghiệp vụ chi tiết cho: Ẩn hoàn toàn bài viết, tin nhắn và thông tin cá nhân của người bị chặn | F10: /network/block-user | G10: Hội Viên | H10: Khẩn cấp | I10: 0.5 | J10: 1.5 | K10: 0.5 | L10: =SUM(I10:K10) | M10: 100 | N10: Hoàn thành Dev | O10: Passed | P10: Đạt UAT | Q10: Bi-directional Exclusion Filter
A11: WBS-NETWORK-0207 | B11: Mạng Lưới Kết Nối & Danh Bạ Doanh Nhân B2B | C11: Mạng Lưới Doanh Nhân & Đối Tác [Giai đoạn: Khởi Tạo, Phân Tích Nghiệp Vụ & Mô Hình Dữ Liệu] | D11: [Kiến Trúc & Schema] Mở chặn người dùng (Unblock User) trong màn hình quản lý bảo mật | E11: Phân tích yêu cầu nghiệp vụ, thiết kế bảng dữ liệu CSDL PostgreSQL, đặc tả API RESTful và luồng nghiệp vụ chi tiết cho: Cho phép khôi phục hiển thị và tìm kiếm lại người dùng trong danh bạ | F11: /settings/blocked-users | G11: Hội Viên | H11: Trung bình | I11: 0.5 | J11: 1.5 | K11: 0.5 | L11: =SUM(I11:K11) | M11: 100 | N11: Hoàn thành Dev | O11: Passed | P11: Đạt UAT | Q11: Security Settings Unblock
A12: WBS-NETWORK-0208 | B12: Mạng Lưới Kết Nối & Danh Bạ Doanh Nhân B2B | C12: Mạng Lưới Doanh Nhân & Đối Tác [Giai đoạn: Khởi Tạo, Phân Tích Nghiệp Vụ & Mô Hình Dữ Liệu] | D12: [Kiến Trúc & Schema] Báo cáo vi phạm (Report User) hành vi giả mạo hoặc lừa đảo | E12: Phân tích yêu cầu nghiệp vụ, thiết kế bảng dữ liệu CSDL PostgreSQL, đặc tả API RESTful và luồng nghiệp vụ chi tiết cho: Gửi báo cáo kèm bằng chứng ảnh chụp màn hình tới Ban Kiểm Tra | F12: /network/report-user | G12: Hội Viên | H12: Cao | I12: 0.5 | J12: 1.5 | K12: 0.5 | L12: =SUM(I12:K12) | M12: 100 | N12: Hoàn thành Dev | O12: Passed | P12: Đạt UAT | Q12: Disciplinary Review Queue
A13: WBS-NETWORK-0209 | B13: Mạng Lưới Kết Nối & Danh Bạ Doanh Nhân B2B | C13: Mạng Lưới Doanh Nhân & Đối Tác [Giai đoạn: Khởi Tạo, Phân Tích Nghiệp Vụ & Mô Hình Dữ Liệu] | D13: [Kiến Trúc & Schema] Đề xuất mối quan hệ chung (Mutual Connections Finder) | E13: Phân tích yêu cầu nghiệp vụ, thiết kế bảng dữ liệu CSDL PostgreSQL, đặc tả API RESTful và luồng nghiệp vụ chi tiết cho: Hiển thị số lượng bạn chung giữa 2 doanh nhân để tăng độ tin cậy | F13: /network/mutual | G13: Hội Viên | H13: Cao | I13: 0.5 | J13: 1.5 | K13: 0.5 | L13: =SUM(I13:K13) | M13: 100 | N13: Hoàn thành Dev | O13: Passed | P13: Đạt UAT | Q13: Graph Network Query
A14: WBS-NETWORK-0210 | B14: Mạng Lưới Kết Nối & Danh Bạ Doanh Nhân B2B | C14: Mạng Lưới Doanh Nhân & Đối Tác [Giai đoạn: Khởi Tạo, Phân Tích Nghiệp Vụ & Mô Hình Dữ Liệu] | D14: [Kiến Trúc & Schema] Gắn thẻ ghi chú quan hệ đối tác (Private Notes & Tags) | E14: Phân tích yêu cầu nghiệp vụ, thiết kế bảng dữ liệu CSDL PostgreSQL, đặc tả API RESTful và luồng nghiệp vụ chi tiết cho: Ghi chép mật về thói quen, sở thích, ngày sinh nhật, chỉ mình xem được | F14: /network/contact-notes | G14: Hội Viên | H14: Cao | I14: 0.5 | J14: 1.5 | K14: 0.5 | L14: =SUM(I14:K14) | M14: 100 | N14: Hoàn thành Dev | O14: Passed | P14: Đạt UAT | Q14: Encrypted Private Notes
A15: WBS-NETWORK-0211 | B15: Mạng Lưới Kết Nối & Danh Bạ Doanh Nhân B2B | C15: Mạng Lưới Doanh Nhân & Đối Tác [Giai đoạn: Khởi Tạo, Phân Tích Nghiệp Vụ & Mô Hình Dữ Liệu] | D15: [Kiến Trúc & Schema] Trao thẻ danh thiếp điện tử 1 chạm NFC (Tap to Connect) | E15: Phân tích yêu cầu nghiệp vụ, thiết kế bảng dữ liệu CSDL PostgreSQL, đặc tả API RESTful và luồng nghiệp vụ chi tiết cho: Truyền thông tin thẻ qua sóng NFC tần số 13.56MHz không cần cài app | F15: /nfc/tap-share | G15: Hội Viên | H15: Khẩn cấp | I15: 0.5 | J15: 1.5 | K15: 0.5 | L15: =SUM(I15:K15) | M15: 100 | N15: Hoàn thành Dev | O15: Passed | P15: Đạt UAT | Q15: Web NFC API Interop
A16: WBS-NETWORK-0212 | B16: Mạng Lưới Kết Nối & Danh Bạ Doanh Nhân B2B | C16: Mạng Lưới Doanh Nhân & Đối Tác [Giai đoạn: Khởi Tạo, Phân Tích Nghiệp Vụ & Mô Hình Dữ Liệu] | D16: [Kiến Trúc & Schema] Sinh mã QR cá nhân hóa động cho danh thiếp điện tử | E16: Phân tích yêu cầu nghiệp vụ, thiết kế bảng dữ liệu CSDL PostgreSQL, đặc tả API RESTful và luồng nghiệp vụ chi tiết cho: Mã QR chứa link slug độc bản, có logo hiệp hội ở chính giữa | F16: /cards/my-qr | G16: Hội Viên | H16: Cao | I16: 0.5 | J16: 1.5 | K16: 0.5 | L16: =SUM(I16:K16) | M16: 100 | N16: Hoàn thành Dev | O16: Passed | P16: Đạt UAT | Q16: Canvas QR Generator
... A104: WBS-NETWORK-0300 | B104: Mạng Lưới Kết Nối & Danh Bạ Doanh Nhân B2B | C104: Mạng Lưới Doanh Nhân & Đối Tác [Giai đoạn: Kiểm Thử Tự Động Toàn Diện E2E, Hiệu Năng & Nghiệm Thu UAT] | D104: [Kiểm Thử E2E & UAT] Xuất danh bạ đối tác kết nối ra file Excel định dạng chuẩn | E104: Kiểm thử hộp đen/hộp trắng toàn diện, kiểm tra tải đồng thời, đối soát dữ liệu và nghiệm thu Ban Lãnh Đạo: Xuất danh sách gồm họ tên, công ty, email, số điện thoại, ngày kết nối | F104: /network/export-excel | G104: Hội Viên | H104: Cao | I104: 0.5 | J104: 0.5 | K104: 2 | L104: =SUM(I104:K104) | M104: 100 | N104: Hoàn thành Dev | O104: Passed | P104: Đạt UAT | Q104: ExcelJS Export Engine
B105: TỔNG CỘNG PHÂN HỆ | I105: =SUM(I5:I104) | J105: =SUM(J5:J104) | K105: =SUM(K5:K104) | L105: =SUM(L5:L104) | M105: =AVERAGE(M5:M104)

Sheet WBS_04_MOMENTS_COMMUNITY
A1: VIONE MASTER WBS: BẢNG TIN MOMENTS, ĐA PHƯƠNG TIỆN & CỘNG ĐỒNG
A3: Tài liệu phạm vi chi tiết PMO Enterprise: 100 tác vụ chuyên sâu • Cập nhật: 2026-09-13
A4: Mã WBS | B4: Phân Hệ | C4: Hạng Mục Cha (Epic / Phase) | D4: Chức Năng Con Chi Tiết (User Story / Work Package) | E4: Mô Tả Luồng Nghiệp Vụ & Xử Lý Kỹ Thuật (Chi Tiết Chuyên Gia) | F4: Tuyến Đường / Endpoint / Screen | G4: Vai Trò Thao Tác (Actor) | H4: Mức Độ Ưu Tiên | I4: Ước Lượng FE (Man-days) | J4: Ước Lượng BE (Man-days) | K4: Ước Lượng QA (Man-days) | L4: Tổng Công Việc (Man-days) | M4: Tiến Độ (%) | N4: Trạng Thái Dev | O4: Trạng Thái Kiểm Thử | P4: Trạng Thái Nghiệm Thu | Q4: Ghi Chú Kỹ Thuật & Kiến Trúc Vận Hành
A5: WBS-MOMENTS-0301 | B5: Bảng Tin Moments, Đa Phương Tiện & Cộng Đồng | C5: Bảng Tin Giao Thương & Cộng Đồng [Giai đoạn: Khởi Tạo, Phân Tích Nghiệp Vụ & Mô Hình Dữ Liệu] | D5: [Kiến Trúc & Schema] Đăng bài khoảnh khắc giao thương đa ảnh chuẩn Facebook-grade | E5: Phân tích yêu cầu nghiệp vụ, thiết kế bảng dữ liệu CSDL PostgreSQL, đặc tả API RESTful và luồng nghiệp vụ chi tiết cho: Cho phép tải tối đa 6 ảnh chất lượng cao, xóa ảnh, nén ảnh client | F5: /moments/create | G5: Hội Viên | H5: Khẩn cấp | I5: 0.5 | J5: 1.5 | K5: 0.5 | L5: =SUM(I5:K5) | M5: 100 | N5: Hoàn thành Dev | O5: Passed | P5: Đạt UAT | Q5: MinIO / Supabase Storage
A6: WBS-MOMENTS-0302 | B6: Bảng Tin Moments, Đa Phương Tiện & Cộng Đồng | C6: Bảng Tin Giao Thương & Cộng Đồng [Giai đoạn: Khởi Tạo, Phân Tích Nghiệp Vụ & Mô Hình Dữ Liệu] | D6: [Kiến Trúc & Schema] Gắn thẻ đối tác doanh nghiệp (@mention) trong bài viết | E6: Phân tích yêu cầu nghiệp vụ, thiết kế bảng dữ liệu CSDL PostgreSQL, đặc tả API RESTful và luồng nghiệp vụ chi tiết cho: Tìm kiếm nhanh doanh nhân trong mạng lưới, gửi thông báo tức thì | F6: /moments/tagging | G6: Hội Viên | H6: Cao | I6: 0.5 | J6: 1.5 | K6: 0.5 | L6: =SUM(I6:K6) | M6: 100 | N6: Hoàn thành Dev | O6: Passed | P6: Đạt UAT | Q6: Mention Parser & Notification
A7: WBS-MOMENTS-0303 | B7: Bảng Tin Moments, Đa Phương Tiện & Cộng Đồng | C7: Bảng Tin Giao Thương & Cộng Đồng [Giai đoạn: Khởi Tạo, Phân Tích Nghiệp Vụ & Mô Hình Dữ Liệu] | D7: [Kiến Trúc & Schema] Gắn địa điểm check-in tại hội trường, khách sạn, sân golf | E7: Phân tích yêu cầu nghiệp vụ, thiết kế bảng dữ liệu CSDL PostgreSQL, đặc tả API RESTful và luồng nghiệp vụ chi tiết cho: Tìm kiếm địa điểm thực tế, lưu trữ tọa độ kinh độ/vĩ độ GPS | F7: /moments/checkin | G7: Hội Viên | H7: Trung bình | I7: 0.5 | J7: 1.5 | K7: 0.5 | L7: =SUM(I7:K7) | M7: 100 | N7: Hoàn thành Dev | O7: Passed | P7: Đạt UAT | Q7: Geolocation Tagging
A8: WBS-MOMENTS-0304 | B8: Bảng Tin Moments, Đa Phương Tiện & Cộng Đồng | C8: Bảng Tin Giao Thương & Cộng Đồng [Giai đoạn: Khởi Tạo, Phân Tích Nghiệp Vụ & Mô Hình Dữ Liệu] | D8: [Kiến Trúc & Schema] Tương tác thả cảm xúc B2B (Thích, Bắt tay, Hợp tác, Vinh danh) | E8: Phân tích yêu cầu nghiệp vụ, thiết kế bảng dữ liệu CSDL PostgreSQL, đặc tả API RESTful và luồng nghiệp vụ chi tiết cho: Hỗ trợ 5 biểu tượng cảm xúc chuyên biệt cho giới doanh nhân | F8: /moments/reactions | G8: Hội Viên | H8: Cao | I8: 0.5 | J8: 1.5 | K8: 0.5 | L8: =SUM(I8:K8) | M8: 100 | N8: Hoàn thành Dev | O8: Passed | P8: Đạt UAT | Q8: Realtime Reaction Dispatcher
A9: WBS-MOMENTS-0305 | B9: Bảng Tin Moments, Đa Phương Tiện & Cộng Đồng | C9: Bảng Tin Giao Thương & Cộng Đồng [Giai đoạn: Khởi Tạo, Phân Tích Nghiệp Vụ & Mô Hình Dữ Liệu] | D9: [Kiến Trúc & Schema] Bình luận bài viết đính kèm hình ảnh tài liệu hợp tác | E9: Phân tích yêu cầu nghiệp vụ, thiết kế bảng dữ liệu CSDL PostgreSQL, đặc tả API RESTful và luồng nghiệp vụ chi tiết cho: Bình luận trao đổi cơ hội, xem trước ảnh và mở Lightbox phóng to | F9: /moments/comments | G9: Hội Viên | H9: Cao | I9: 0.5 | J9: 1.5 | K9: 0.5 | L9: =SUM(I9:K9) | M9: 100 | N9: Hoàn thành Dev | O9: Passed | P9: Đạt UAT | Q9: Comment Image Attachments
A10: WBS-MOMENTS-0306 | B10: Bảng Tin Moments, Đa Phương Tiện & Cộng Đồng | C10: Bảng Tin Giao Thương & Cộng Đồng [Giai đoạn: Khởi Tạo, Phân Tích Nghiệp Vụ & Mô Hình Dữ Liệu] | D10: [Kiến Trúc & Schema] Bình luận phản hồi lồng nhau đa cấp (Nested Reply Comments) | E10: Phân tích yêu cầu nghiệp vụ, thiết kế bảng dữ liệu CSDL PostgreSQL, đặc tả API RESTful và luồng nghiệp vụ chi tiết cho: Hỗ trợ trả lời trực tiếp từng bình luận, thông báo theo cây thảo luận | F10: /moments/replies | G10: Hội Viên | H10: Trung bình | I10: 0.5 | J10: 1.5 | K10: 0.5 | L10: =SUM(I10:K10) | M10: 100 | N10: Hoàn thành Dev | O10: Passed | P10: Đạt UAT | Q10: Hierarchical Tree Comments
A11: WBS-MOMENTS-0307 | B11: Bảng Tin Moments, Đa Phương Tiện & Cộng Đồng | C11: Bảng Tin Giao Thương & Cộng Đồng [Giai đoạn: Khởi Tạo, Phân Tích Nghiệp Vụ & Mô Hình Dữ Liệu] | D11: [Kiến Trúc & Schema] Chỉnh sửa và xóa bài viết Moments có xác nhận an toàn | E11: Phân tích yêu cầu nghiệp vụ, thiết kế bảng dữ liệu CSDL PostgreSQL, đặc tả API RESTful và luồng nghiệp vụ chi tiết cho: Cho phép tác giả sửa nội dung, xóa bài viết kèm xóa ảnh lưu trữ | F11: /moments/edit-delete | G11: Hội Viên | H11: Cao | I11: 0.5 | J11: 1.5 | K11: 0.5 | L11: =SUM(I11:K11) | M11: 100 | N11: Hoàn thành Dev | O11: Passed | P11: Đạt UAT | Q11: Cascade Storage Cleanup
A12: WBS-MOMENTS-0308 | B12: Bảng Tin Moments, Đa Phương Tiện & Cộng Đồng | C12: Bảng Tin Giao Thương & Cộng Đồng [Giai đoạn: Khởi Tạo, Phân Tích Nghiệp Vụ & Mô Hình Dữ Liệu] | D12: [Kiến Trúc & Schema] Khởi tạo Phân ban / Câu lạc bộ chuyên môn trong Hiệp hội | E12: Phân tích yêu cầu nghiệp vụ, thiết kế bảng dữ liệu CSDL PostgreSQL, đặc tả API RESTful và luồng nghiệp vụ chi tiết cho: Khai báo CLB Bất động sản, CLB Công nghệ, CLB Golf doanh nhân | F12: /communities/create | G12: Ban Chấp Hành | H12: Khẩn cấp | I12: 0.5 | J12: 1.5 | K12: 0.5 | L12: =SUM(I12:K12) | M12: 100 | N12: Hoàn thành Dev | O12: Passed | P12: Đạt UAT | Q12: Multi-club Architecture
A13: WBS-MOMENTS-0309 | B13: Bảng Tin Moments, Đa Phương Tiện & Cộng Đồng | C13: Bảng Tin Giao Thương & Cộng Đồng [Giai đoạn: Khởi Tạo, Phân Tích Nghiệp Vụ & Mô Hình Dữ Liệu] | D13: [Kiến Trúc & Schema] Gia nhập hoặc rời khỏi Câu lạc bộ / Phân ban chuyên môn | E13: Phân tích yêu cầu nghiệp vụ, thiết kế bảng dữ liệu CSDL PostgreSQL, đặc tả API RESTful và luồng nghiệp vụ chi tiết cho: Hội viên đăng ký tham gia CLB, Thư ký CLB duyệt thành viên mới | F13: /communities/membership | G13: Hội Viên | H13: Cao | I13: 0.5 | J13: 1.5 | K13: 0.5 | L13: =SUM(I13:K13) | M13: 100 | N13: Hoàn thành Dev | O13: Passed | P13: Đạt UAT | Q13: Club Member Roster
A14: WBS-MOMENTS-0310 | B14: Bảng Tin Moments, Đa Phương Tiện & Cộng Đồng | C14: Bảng Tin Giao Thương & Cộng Đồng [Giai đoạn: Khởi Tạo, Phân Tích Nghiệp Vụ & Mô Hình Dữ Liệu] | D14: [Kiến Trúc & Schema] Ghim bài viết quan trọng (Pin Post) lên đầu bảng tin CLB | E14: Phân tích yêu cầu nghiệp vụ, thiết kế bảng dữ liệu CSDL PostgreSQL, đặc tả API RESTful và luồng nghiệp vụ chi tiết cho: Trưởng ban ghim thông báo đại hội, nghị quyết hoặc quy chế hoạt động | F14: /communities/pin-post | G14: Trưởng Ban | H14: Trung bình | I14: 0.5 | J14: 1.5 | K14: 0.5 | L14: =SUM(I14:K14) | M14: 100 | N14: Hoàn thành Dev | O14: Passed | P14: Đạt UAT | Q14: Sticky Post Priority Flag
A15: WBS-MOMENTS-0311 | B15: Bảng Tin Moments, Đa Phương Tiện & Cộng Đồng | C15: Bảng Tin Giao Thương & Cộng Đồng [Giai đoạn: Khởi Tạo, Phân Tích Nghiệp Vụ & Mô Hình Dữ Liệu] | D15: [Kiến Trúc & Schema] Kiểm duyệt bài viết tự động chống ngôn từ tiêu cực bằng AI | E15: Phân tích yêu cầu nghiệp vụ, thiết kế bảng dữ liệu CSDL PostgreSQL, đặc tả API RESTful và luồng nghiệp vụ chi tiết cho: Quét nội dung bài viết trước khi xuất bản, gắn cờ bài vi phạm | F15: /moments/ai-moderation | G15: Hệ Thống Tự Động | H15: Cao | I15: 0.5 | J15: 1.5 | K15: 0.5 | L15: =SUM(I15:K15) | M15: 100 | N15: Hoàn thành Dev | O15: Passed | P15: Đạt UAT | Q15: AI NLP Text Moderation
A16: WBS-MOMENTS-0312 | B16: Bảng Tin Moments, Đa Phương Tiện & Cộng Đồng | C16: Bảng Tin Giao Thương & Cộng Đồng [Giai đoạn: Khởi Tạo, Phân Tích Nghiệp Vụ & Mô Hình Dữ Liệu] | D16: [Kiến Trúc & Schema] Xem ảnh phóng to toàn màn hình dạng Lightbox có vuốt chạm | E16: Phân tích yêu cầu nghiệp vụ, thiết kế bảng dữ liệu CSDL PostgreSQL, đặc tả API RESTful và luồng nghiệp vụ chi tiết cho: Hỗ trợ cử chỉ chạm vuốt sang ảnh kế tiếp trên màn hình di động | F16: /components/lightbox | G16: Người Dùng | H16: Cao | I16: 0.5 | J16: 1.5 | K16: 0.5 | L16: =SUM(I16:K16) | M16: 100 | N16: Hoàn thành Dev | O16: Passed | P16: Đạt UAT | Q16: Touch Gesture Lightbox
... A104: WBS-MOMENTS-0400 | B104: Bảng Tin Moments, Đa Phương Tiện & Cộng Đồng | C104: Bảng Tin Giao Thương & Cộng Đồng [Giai đoạn: Kiểm Thử Tự Động Toàn Diện E2E, Hiệu Năng & Nghiệm Thu UAT] | D104: [Kiểm Thử E2E & UAT] Thống kê tương tác bài viết (Lượt xem, tiếp cận, chia sẻ) | E104: Kiểm thử hộp đen/hộp trắng toàn diện, kiểm tra tải đồng thời, đối soát dữ liệu và nghiệm thu Ban Lãnh Đạo: Báo cáo hiệu quả lan tỏa bài viết của doanh nghiệp trên bảng tin | F104: /moments/post-metrics | G104: Hội Viên | H104: Trung bình | I104: 0.5 | J104: 0.5 | K104: 2 | L104: =SUM(I104:K104) | M104: 100 | N104: Hoàn thành Dev | O104: Passed | P104: Đạt UAT | Q104: Impression Counter
B105: TỔNG CỘNG PHÂN HỆ | I105: =SUM(I5:I104) | J105: =SUM(J5:J104) | K105: =SUM(K5:K104) | L105: =SUM(L5:L104) | M105: =AVERAGE(M5:M104)

Sheet WBS_05_CHAT_VIDEO_CALL
A1: VIONE MASTER WBS: NHẮN TIN REALTIME & HỌP TRỰC TUYẾN VIDEO CALL
A3: Tài liệu phạm vi chi tiết PMO Enterprise: 100 tác vụ chuyên sâu • Cập nhật: 2026-09-13
A4: Mã WBS | B4: Phân Hệ | C4: Hạng Mục Cha (Epic / Phase) | D4: Chức Năng Con Chi Tiết (User Story / Work Package) | E4: Mô Tả Luồng Nghiệp Vụ & Xử Lý Kỹ Thuật (Chi Tiết Chuyên Gia) | F4: Tuyến Đường / Endpoint / Screen | G4: Vai Trò Thao Tác (Actor) | H4: Mức Độ Ưu Tiên | I4: Ước Lượng FE (Man-days) | J4: Ước Lượng BE (Man-days) | K4: Ước Lượng QA (Man-days) | L4: Tổng Công Việc (Man-days) | M4: Tiến Độ (%) | N4: Trạng Thái Dev | O4: Trạng Thái Kiểm Thử | P4: Trạng Thái Nghiệm Thu | Q4: Ghi Chú Kỹ Thuật & Kiến Trúc Vận Hành
A5: WBS-CHAT_CALL-0401 | B5: Nhắn Tin Realtime & Họp Trực Tuyến Video Call | C5: Giao Tiếp Realtime & Họp Trực Tuyến [Giai đoạn: Khởi Tạo, Phân Tích Nghiệp Vụ & Mô Hình Dữ Liệu] | D5: [Kiến Trúc & Schema] Kênh chat 1-on-1 thời gian thực qua WebSocket Gateway | E5: Phân tích yêu cầu nghiệp vụ, thiết kế bảng dữ liệu CSDL PostgreSQL, đặc tả API RESTful và luồng nghiệp vụ chi tiết cho: Độ trễ dưới 0.05 giây, âm thanh thông báo sang trọng, gõ phím realtime | F5: /chat/:peerId | G5: Hội Viên | H5: Khẩn cấp | I5: 0.5 | J5: 1.5 | K5: 0.5 | L5: =SUM(I5:K5) | M5: 100 | N5: Hoàn thành Dev | O5: Passed | P5: Đạt UAT | Q5: Socket.IO / Supabase Realtime
A6: WBS-CHAT_CALL-0402 | B6: Nhắn Tin Realtime & Họp Trực Tuyến Video Call | C6: Giao Tiếp Realtime & Họp Trực Tuyến [Giai đoạn: Khởi Tạo, Phân Tích Nghiệp Vụ & Mô Hình Dữ Liệu] | D6: [Kiến Trúc & Schema] Nhắn tin nhóm thảo luận theo Dự án / Phân ban Hiệp hội | E6: Phân tích yêu cầu nghiệp vụ, thiết kế bảng dữ liệu CSDL PostgreSQL, đặc tả API RESTful và luồng nghiệp vụ chi tiết cho: Tạo nhóm chat đến 200 lãnh đạo doanh nghiệp, phân quyền Admin nhóm | F6: /chat/group | G6: Hội Viên | H6: Khẩn cấp | I6: 0.5 | J6: 1.5 | K6: 0.5 | L6: =SUM(I6:K6) | M6: 100 | N6: Hoàn thành Dev | O6: Passed | P6: Đạt UAT | Q6: Group Channel Multiplexing
A7: WBS-CHAT_CALL-0403 | B7: Nhắn Tin Realtime & Họp Trực Tuyến Video Call | C7: Giao Tiếp Realtime & Họp Trực Tuyến [Giai đoạn: Khởi Tạo, Phân Tích Nghiệp Vụ & Mô Hình Dữ Liệu] | D7: [Kiến Trúc & Schema] Gửi tài liệu hợp đồng, bảng báo giá PDF/Excel đến 50MB | E7: Phân tích yêu cầu nghiệp vụ, thiết kế bảng dữ liệu CSDL PostgreSQL, đặc tả API RESTful và luồng nghiệp vụ chi tiết cho: Hỗ trợ kéo thả gửi tệp tin văn bản, xem trước trực tiếp trên giao diện | F7: /chat/upload-docs | G7: Hội Viên | H7: Cao | I7: 0.5 | J7: 1.5 | K7: 0.5 | L7: =SUM(I7:K7) | M7: 100 | N7: Hoàn thành Dev | O7: Passed | P7: Đạt UAT | Q7: Virus Scanning & S3 Storage
A8: WBS-CHAT_CALL-0404 | B8: Nhắn Tin Realtime & Họp Trực Tuyến Video Call | C8: Giao Tiếp Realtime & Họp Trực Tuyến [Giai đoạn: Khởi Tạo, Phân Tích Nghiệp Vụ & Mô Hình Dữ Liệu] | D8: [Kiến Trúc & Schema] Ghi âm và gửi tin nhắn thoại (Voice Note) chất lượng cao | E8: Phân tích yêu cầu nghiệp vụ, thiết kế bảng dữ liệu CSDL PostgreSQL, đặc tả API RESTful và luồng nghiệp vụ chi tiết cho: Thu âm trực tiếp trên trình duyệt, nén âm thanh định dạng AAC/Opus | F8: /chat/voice-note | G8: Hội Viên | H8: Cao | I8: 0.5 | J8: 1.5 | K8: 0.5 | L8: =SUM(I8:K8) | M8: 100 | N8: Hoàn thành Dev | O8: Passed | P8: Đạt UAT | Q8: MediaRecorder API Audio
A9: WBS-CHAT_CALL-0405 | B9: Nhắn Tin Realtime & Họp Trực Tuyến Video Call | C9: Giao Tiếp Realtime & Họp Trực Tuyến [Giai đoạn: Khởi Tạo, Phân Tích Nghiệp Vụ & Mô Hình Dữ Liệu] | D9: [Kiến Trúc & Schema] Hiển thị trạng thái đã nhận, đã xem tin nhắn (Read Receipts) | E9: Phân tích yêu cầu nghiệp vụ, thiết kế bảng dữ liệu CSDL PostgreSQL, đặc tả API RESTful và luồng nghiệp vụ chi tiết cho: Cập nhật dấu tích xanh khi đối tác mở xem tin nhắn trong phòng chat | F9: /chat/read-receipts | G9: Hội Viên | H9: Trung bình | I9: 0.5 | J9: 1.5 | K9: 0.5 | L9: =SUM(I9:K9) | M9: 100 | N9: Hoàn thành Dev | O9: Passed | P9: Đạt UAT | Q9: Delivered & Seen Events
A10: WBS-CHAT_CALL-0406 | B10: Nhắn Tin Realtime & Họp Trực Tuyến Video Call | C10: Giao Tiếp Realtime & Họp Trực Tuyến [Giai đoạn: Khởi Tạo, Phân Tích Nghiệp Vụ & Mô Hình Dữ Liệu] | D10: [Kiến Trúc & Schema] Tìm kiếm nội dung tin nhắn và tệp đính kèm trong lịch sử chat | E10: Phân tích yêu cầu nghiệp vụ, thiết kế bảng dữ liệu CSDL PostgreSQL, đặc tả API RESTful và luồng nghiệp vụ chi tiết cho: Tìm kiếm từ khóa đàm phán hợp đồng, lọc theo tệp tin và hình ảnh | F10: /chat/search-history | G10: Hội Viên | H10: Cao | I10: 0.5 | J10: 1.5 | K10: 0.5 | L10: =SUM(I10:K10) | M10: 100 | N10: Hoàn thành Dev | O10: Passed | P10: Đạt UAT | Q10: Chat Message Indexing
A11: WBS-CHAT_CALL-0407 | B11: Nhắn Tin Realtime & Họp Trực Tuyến Video Call | C11: Giao Tiếp Realtime & Họp Trực Tuyến [Giai đoạn: Khởi Tạo, Phân Tích Nghiệp Vụ & Mô Hình Dữ Liệu] | D11: [Kiến Trúc & Schema] Cuộc gọi thoại (Audio Call) chất lượng cao qua WebRTC | E11: Phân tích yêu cầu nghiệp vụ, thiết kế bảng dữ liệu CSDL PostgreSQL, đặc tả API RESTful và luồng nghiệp vụ chi tiết cho: Kết nối thoại P2P mã hóa đầu cuối, âm thanh chuẩn HD rõ nét | F11: /call/audio | G11: Hội Viên | H11: Khẩn cấp | I11: 0.5 | J11: 1.5 | K11: 0.5 | L11: =SUM(I11:K11) | M11: 100 | N11: Hoàn thành Dev | O11: Passed | P11: Đạt UAT | Q11: WebRTC PeerConnection Audio
A12: WBS-CHAT_CALL-0408 | B12: Nhắn Tin Realtime & Họp Trực Tuyến Video Call | C12: Giao Tiếp Realtime & Họp Trực Tuyến [Giai đoạn: Khởi Tạo, Phân Tích Nghiệp Vụ & Mô Hình Dữ Liệu] | D12: [Kiến Trúc & Schema] Cuộc gọi Video 1-on-1 trực tiếp bảo mật giữa 2 doanh nhân | E12: Phân tích yêu cầu nghiệp vụ, thiết kế bảng dữ liệu CSDL PostgreSQL, đặc tả API RESTful và luồng nghiệp vụ chi tiết cho: Truyền hình ảnh Full HD 1080p, tự động điều chỉnh bitrate khi mạng yếu | F12: /call/video-1on1 | G12: Hội Viên | H12: Khẩn cấp | I12: 0.5 | J12: 1.5 | K12: 0.5 | L12: =SUM(I12:K12) | M12: 100 | N12: Hoàn thành Dev | O12: Passed | P12: Đạt UAT | Q12: WebRTC Adaptive Bitrate
A13: WBS-CHAT_CALL-0409 | B13: Nhắn Tin Realtime & Họp Trực Tuyến Video Call | C13: Giao Tiếp Realtime & Họp Trực Tuyến [Giai đoạn: Khởi Tạo, Phân Tích Nghiệp Vụ & Mô Hình Dữ Liệu] | D13: [Kiến Trúc & Schema] Họp trực tuyến nhiều bên (Video Conference Room) Ban Chấp Hành | E13: Phân tích yêu cầu nghiệp vụ, thiết kế bảng dữ liệu CSDL PostgreSQL, đặc tả API RESTful và luồng nghiệp vụ chi tiết cho: Hỗ trợ phòng họp đến 16 đại biểu, hiển thị lưới Grid thông minh | F13: /call/conference | G13: Ban Chấp Hành | H13: Khẩn cấp | I13: 0.5 | J13: 1.5 | K13: 0.5 | L13: =SUM(I13:K13) | M13: 100 | N13: Hoàn thành Dev | O13: Passed | P13: Đạt UAT | Q13: SFU Media Server Integration
A14: WBS-CHAT_CALL-0410 | B14: Nhắn Tin Realtime & Họp Trực Tuyến Video Call | C14: Giao Tiếp Realtime & Họp Trực Tuyến [Giai đoạn: Khởi Tạo, Phân Tích Nghiệp Vụ & Mô Hình Dữ Liệu] | D14: [Kiến Trúc & Schema] Chia sẻ màn hình máy tính (Screen Sharing) khi thuyết trình dự án | E14: Phân tích yêu cầu nghiệp vụ, thiết kế bảng dữ liệu CSDL PostgreSQL, đặc tả API RESTful và luồng nghiệp vụ chi tiết cho: Cho phép chia sẻ slide thuyết trình, bảng tính Excel trong cuộc gọi | F14: /call/screen-share | G14: Diễn Giả | H14: Cao | I14: 0.5 | J14: 1.5 | K14: 0.5 | L14: =SUM(I14:K14) | M14: 100 | N14: Hoàn thành Dev | O14: Passed | P14: Đạt UAT | Q14: getDisplayMedia Web API
A15: WBS-CHAT_CALL-0411 | B15: Nhắn Tin Realtime & Họp Trực Tuyến Video Call | C15: Giao Tiếp Realtime & Họp Trực Tuyến [Giai đoạn: Khởi Tạo, Phân Tích Nghiệp Vụ & Mô Hình Dữ Liệu] | D15: [Kiến Trúc & Schema] Tính năng giơ tay phát biểu trong phòng họp trực tuyến | E15: Phân tích yêu cầu nghiệp vụ, thiết kế bảng dữ liệu CSDL PostgreSQL, đặc tả API RESTful và luồng nghiệp vụ chi tiết cho: Đại biểu bấm giơ tay, chủ tọa nhận thông báo và cấp quyền mở mic | F15: /call/raise-hand | G15: Đại Biểu | H15: Cao | I15: 0.5 | J15: 1.5 | K15: 0.5 | L15: =SUM(I15:K15) | M15: 100 | N15: Hoàn thành Dev | O15: Passed | P15: Đạt UAT | Q15: Floor Control Signaling
A16: WBS-CHAT_CALL-0412 | B16: Nhắn Tin Realtime & Họp Trực Tuyến Video Call | C16: Giao Tiếp Realtime & Họp Trực Tuyến [Giai đoạn: Khởi Tạo, Phân Tích Nghiệp Vụ & Mô Hình Dữ Liệu] | D16: [Kiến Trúc & Schema] Ghi âm và lưu trữ biên bản cuộc họp trực tuyến lên đám mây | E16: Phân tích yêu cầu nghiệp vụ, thiết kế bảng dữ liệu CSDL PostgreSQL, đặc tả API RESTful và luồng nghiệp vụ chi tiết cho: Lưu file MP4/WebM cuộc họp lên MinIO phục vụ lưu trữ văn kiện | F16: /call/recording | G16: Thư Ký Cuộc Họp | H16: Cao | I16: 0.5 | J16: 1.5 | K16: 0.5 | L16: =SUM(I16:K16) | M16: 100 | N16: Hoàn thành Dev | O16: Passed | P16: Đạt UAT | Q16: Server-side Media Recorder
... A104: WBS-CHAT_CALL-0500 | B104: Nhắn Tin Realtime & Họp Trực Tuyến Video Call | C104: Giao Tiếp Realtime & Họp Trực Tuyến [Giai đoạn: Kiểm Thử Tự Động Toàn Diện E2E, Hiệu Năng & Nghiệm Thu UAT] | D104: [Kiểm Thử E2E & UAT] Báo cáo thống kê thời lượng và số lượt họp trực tuyến | E104: Kiểm thử hộp đen/hộp trắng toàn diện, kiểm tra tải đồng thời, đối soát dữ liệu và nghiệm thu Ban Lãnh Đạo: Tổng kết số giờ họp của Ban Lãnh Đạo và các phân ban theo tháng | F104: /call/analytics | G104: Ban Thư Ký | H104: Trung bình | I104: 0.5 | J104: 0.5 | K104: 2 | L104: =SUM(I104:K104) | M104: 100 | N104: Hoàn thành Dev | O104: Passed | P104: Đạt UAT | Q104: Meeting Stats Aggregator
B105: TỔNG CỘNG PHÂN HỆ | I105: =SUM(I5:I104) | J105: =SUM(J5:J104) | K105: =SUM(K5:K104) | L105: =SUM(L5:L104) | M105: =AVERAGE(M5:M104)

Sheet WBS_06_CRM_LEADS_REFERRAL
A1: VIONE MASTER WBS: CRM QUẢN TRỊ KHÁCH HÀNG, LEAD & TRAO CƠ HỘI REFERRAL
A3: Tài liệu phạm vi chi tiết PMO Enterprise: 100 tác vụ chuyên sâu • Cập nhật: 2026-09-13
A4: Mã WBS | B4: Phân Hệ | C4: Hạng Mục Cha (Epic / Phase) | D4: Chức Năng Con Chi Tiết (User Story / Work Package) | E4: Mô Tả Luồng Nghiệp Vụ & Xử Lý Kỹ Thuật (Chi Tiết Chuyên Gia) | F4: Tuyến Đường / Endpoint / Screen | G4: Vai Trò Thao Tác (Actor) | H4: Mức Độ Ưu Tiên | I4: Ước Lượng FE (Man-days) | J4: Ước Lượng BE (Man-days) | K4: Ước Lượng QA (Man-days) | L4: Tổng Công Việc (Man-days) | M4: Tiến Độ (%) | N4: Trạng Thái Dev | O4: Trạng Thái Kiểm Thử | P4: Trạng Thái Nghiệm Thu | Q4: Ghi Chú Kỹ Thuật & Kiến Trúc Vận Hành
A5: WBS-CRM_LEAD-0501 | B5: CRM Quản Trị Khách Hàng, Lead & Trao Cơ Hội Referral | C5: Quản Lý Khách Hàng & Cơ Hội Giao Thương [Giai đoạn: Khởi Tạo, Phân Tích Nghiệp Vụ & Mô Hình Dữ Liệu] | D5: [Kiến Trúc & Schema] Tiếp nhận khách hàng tiềm năng (Leads) từ Web Portal & Đặt demo | E5: Phân tích yêu cầu nghiệp vụ, thiết kế bảng dữ liệu CSDL PostgreSQL, đặc tả API RESTful và luồng nghiệp vụ chi tiết cho: Tự động tạo bản ghi lead, gán nguồn thu thập, phân công cán bộ chăm sóc | F5: /crm/leads/ingest | G5: Hệ Thống Tự Động | H5: Khẩn cấp | I5: 0.5 | J5: 1.5 | K5: 0.5 | L5: =SUM(I5:K5) | M5: 100 | N5: Hoàn thành Dev | O5: Passed | P5: Đạt UAT | Q5: Lead Capture Engine
A6: WBS-CRM_LEAD-0502 | B6: CRM Quản Trị Khách Hàng, Lead & Trao Cơ Hội Referral | C6: Quản Lý Khách Hàng & Cơ Hội Giao Thương [Giai đoạn: Khởi Tạo, Phân Tích Nghiệp Vụ & Mô Hình Dữ Liệu] | D6: [Kiến Trúc & Schema] Chấm điểm tiềm năng khách hàng (Lead Scoring Algorithm) | E6: Phân tích yêu cầu nghiệp vụ, thiết kế bảng dữ liệu CSDL PostgreSQL, đặc tả API RESTful và luồng nghiệp vụ chi tiết cho: Tính điểm dựa trên quy mô công ty, doanh thu, độ khớp ngành nghề | F6: /crm/leads/scoring | G6: Trưởng Ban | H6: Cao | I6: 0.5 | J6: 1.5 | K6: 0.5 | L6: =SUM(I6:K6) | M6: 100 | N6: Hoàn thành Dev | O6: Passed | P6: Đạt UAT | Q6: Rule-based Lead Score
A7: WBS-CRM_LEAD-0503 | B7: CRM Quản Trị Khách Hàng, Lead & Trao Cơ Hội Referral | C7: Quản Lý Khách Hàng & Cơ Hội Giao Thương [Giai đoạn: Khởi Tạo, Phân Tích Nghiệp Vụ & Mô Hình Dữ Liệu] | D7: [Kiến Trúc & Schema] Bảng Kanban phễu bán hàng và chăm sóc hội viên (Sales Pipeline) | E7: Phân tích yêu cầu nghiệp vụ, thiết kế bảng dữ liệu CSDL PostgreSQL, đặc tả API RESTful và luồng nghiệp vụ chi tiết cho: Kéo thả thẻ khách hàng qua các giai đoạn: Mới -> Tiếp cận -> Thẩm định -> Kết nạp | F7: /crm/pipeline/kanban | G7: Cán Bộ CRM | H7: Khẩn cấp | I7: 0.5 | J7: 1.5 | K7: 0.5 | L7: =SUM(I7:K7) | M7: 100 | N7: Hoàn thành Dev | O7: Passed | P7: Đạt UAT | Q7: Drag and Drop Kanban UI
A8: WBS-CRM_LEAD-0504 | B8: CRM Quản Trị Khách Hàng, Lead & Trao Cơ Hội Referral | C8: Quản Lý Khách Hàng & Cơ Hội Giao Thương [Giai đoạn: Khởi Tạo, Phân Tích Nghiệp Vụ & Mô Hình Dữ Liệu] | D8: [Kiến Trúc & Schema] Chuyển đổi khách hàng tiềm năng thành Hội viên chính thức 1-click | E8: Phân tích yêu cầu nghiệp vụ, thiết kế bảng dữ liệu CSDL PostgreSQL, đặc tả API RESTful và luồng nghiệp vụ chi tiết cho: Tự động chuyển thông tin Lead sang bảng members, sinh hóa đơn niên liễm | F8: /crm/leads/convert | G8: Thư Ký Hiệp Hội | H8: Khẩn cấp | I8: 0.5 | J8: 1.5 | K8: 0.5 | L8: =SUM(I8:K8) | M8: 100 | N8: Hoàn thành Dev | O8: Passed | P8: Đạt UAT | Q8: Prisma Lead-to-Member Flow
A9: WBS-CRM_LEAD-0505 | B9: CRM Quản Trị Khách Hàng, Lead & Trao Cơ Hội Referral | C9: Quản Lý Khách Hàng & Cơ Hội Giao Thương [Giai đoạn: Khởi Tạo, Phân Tích Nghiệp Vụ & Mô Hình Dữ Liệu] | D9: [Kiến Trúc & Schema] Ghi nhận dòng thời gian tương tác (Activity Timeline & Notes) | E9: Phân tích yêu cầu nghiệp vụ, thiết kế bảng dữ liệu CSDL PostgreSQL, đặc tả API RESTful và luồng nghiệp vụ chi tiết cho: Lưu lịch sử cuộc gọi, biên bản họp, email trao đổi và nhiệm vụ cần làm | F9: /crm/activities/timeline | G9: Cán Bộ CRM | H9: Cao | I9: 0.5 | J9: 1.5 | K9: 0.5 | L9: =SUM(I9:K9) | M9: 100 | N9: Hoàn thành Dev | O9: Passed | P9: Đạt UAT | Q9: Activity Audit Trail
A10: WBS-CRM_LEAD-0506 | B10: CRM Quản Trị Khách Hàng, Lead & Trao Cơ Hội Referral | C10: Quản Lý Khách Hàng & Cơ Hội Giao Thương [Giai đoạn: Khởi Tạo, Phân Tích Nghiệp Vụ & Mô Hình Dữ Liệu] | D10: [Kiến Trúc & Schema] Đặt lịch nhắc việc và hẹn gặp doanh nhân tự động gửi thông báo | E10: Phân tích yêu cầu nghiệp vụ, thiết kế bảng dữ liệu CSDL PostgreSQL, đặc tả API RESTful và luồng nghiệp vụ chi tiết cho: Cảnh báo hạn chót nộp hồ sơ, nhắc lịch gặp mặt trước 30 phút qua SMS/Push | F10: /crm/tasks/reminders | G10: Cán Bộ CRM | H10: Cao | I10: 0.5 | J10: 1.5 | K10: 0.5 | L10: =SUM(I10:K10) | M10: 100 | N10: Hoàn thành Dev | O10: Passed | P10: Đạt UAT | Q10: Task Scheduler Cron
A11: WBS-CRM_LEAD-0507 | B11: CRM Quản Trị Khách Hàng, Lead & Trao Cơ Hội Referral | C11: Quản Lý Khách Hàng & Cơ Hội Giao Thương [Giai đoạn: Khởi Tạo, Phân Tích Nghiệp Vụ & Mô Hình Dữ Liệu] | D11: [Kiến Trúc & Schema] Trao cơ hội kinh doanh (Create Business Referral Opportunity) | E11: Phân tích yêu cầu nghiệp vụ, thiết kế bảng dữ liệu CSDL PostgreSQL, đặc tả API RESTful và luồng nghiệp vụ chi tiết cho: Hội viên A giới thiệu khách hàng lớn cho Hội viên B trong mạng lưới | F11: /crm/referrals/create | G11: Hội Viên | H11: Khẩn cấp | I11: 0.5 | J11: 1.5 | K11: 0.5 | L11: =SUM(I11:K11) | M11: 100 | N11: Hoàn thành Dev | O11: Passed | P11: Đạt UAT | Q11: Referral Tracking Model
A12: WBS-CRM_LEAD-0508 | B12: CRM Quản Trị Khách Hàng, Lead & Trao Cơ Hội Referral | C12: Quản Lý Khách Hàng & Cơ Hội Giao Thương [Giai đoạn: Khởi Tạo, Phân Tích Nghiệp Vụ & Mô Hình Dữ Liệu] | D12: [Kiến Trúc & Schema] Theo dõi trạng thái cơ hội kinh doanh: Đang đàm phán -> Ký kết thành công | E12: Phân tích yêu cầu nghiệp vụ, thiết kế bảng dữ liệu CSDL PostgreSQL, đặc tả API RESTful và luồng nghiệp vụ chi tiết cho: Cập nhật tiến độ tiếp cận khách hàng được giới thiệu, bảo đảm minh bạch | F12: /crm/referrals/:id/track | G12: Hội Viên Nhận | H12: Cao | I12: 0.5 | J12: 1.5 | K12: 0.5 | L12: =SUM(I12:K12) | M12: 100 | N12: Hoàn thành Dev | O12: Passed | P12: Đạt UAT | Q12: Deal Stage Progression
A13: WBS-CRM_LEAD-0509 | B13: CRM Quản Trị Khách Hàng, Lead & Trao Cơ Hội Referral | C13: Quản Lý Khách Hàng & Cơ Hội Giao Thương [Giai đoạn: Khởi Tạo, Phân Tích Nghiệp Vụ & Mô Hình Dữ Liệu] | D13: [Kiến Trúc & Schema] Ghi nhận giá trị hợp đồng thành công và chia hoa hồng cảm ơn | E13: Phân tích yêu cầu nghiệp vụ, thiết kế bảng dữ liệu CSDL PostgreSQL, đặc tả API RESTful và luồng nghiệp vụ chi tiết cho: Xác nhận doanh thu thực tế phát sinh từ cơ hội, ghi nhận đóng góp hiệp hội | F13: /crm/referrals/revenue-slip | G13: Hội Viên | H13: Khẩn cấp | I13: 0.5 | J13: 1.5 | K13: 0.5 | L13: =SUM(I13:K13) | M13: 100 | N13: Hoàn thành Dev | O13: Passed | P13: Đạt UAT | Q13: Commission Settlement
A14: WBS-CRM_LEAD-0510 | B14: CRM Quản Trị Khách Hàng, Lead & Trao Cơ Hội Referral | C14: Quản Lý Khách Hàng & Cơ Hội Giao Thương [Giai đoạn: Khởi Tạo, Phân Tích Nghiệp Vụ & Mô Hình Dữ Liệu] | D14: [Kiến Trúc & Schema] Báo cáo thống kê hiệu quả mạng lưới kết nối kinh doanh (ROI Analytics) | E14: Phân tích yêu cầu nghiệp vụ, thiết kế bảng dữ liệu CSDL PostgreSQL, đặc tả API RESTful và luồng nghiệp vụ chi tiết cho: Biểu đồ tổng giá trị giao thương, top hội viên tích cực trao cơ hội nhất | F14: /crm/reports/referral-kpi | G14: Ban Lãnh Đạo | H14: Cao | I14: 0.5 | J14: 1.5 | K14: 0.5 | L14: =SUM(I14:K14) | M14: 100 | N14: Hoàn thành Dev | O14: Passed | P14: Đạt UAT | Q14: Aggregated BI Metrics
A15: WBS-CRM_LEAD-0511 | B15: CRM Quản Trị Khách Hàng, Lead & Trao Cơ Hội Referral | C15: Quản Lý Khách Hàng & Cơ Hội Giao Thương [Giai đoạn: Khởi Tạo, Phân Tích Nghiệp Vụ & Mô Hình Dữ Liệu] | D15: [Kiến Trúc & Schema] Tích hợp biểu mẫu thu thập thông tin trên trang chủ Landing Page | E15: Phân tích yêu cầu nghiệp vụ, thiết kế bảng dữ liệu CSDL PostgreSQL, đặc tả API RESTful và luồng nghiệp vụ chi tiết cho: Biểu mẫu Đặt Demo nhúng trên Web tự động đẩy dữ liệu về CRM | F15: /crm/lead-forms | G15: Khách Vãng Lai | H15: Cao | I15: 0.5 | J15: 1.5 | K15: 0.5 | L15: =SUM(I15:K15) | M15: 100 | N15: Hoàn thành Dev | O15: Passed | P15: Đạt UAT | Q15: Embeddable Lead Form
A16: WBS-CRM_LEAD-0512 | B16: CRM Quản Trị Khách Hàng, Lead & Trao Cơ Hội Referral | C16: Quản Lý Khách Hàng & Cơ Hội Giao Thương [Giai đoạn: Khởi Tạo, Phân Tích Nghiệp Vụ & Mô Hình Dữ Liệu] | D16: [Kiến Trúc & Schema] Phân công xử lý Lead tự động theo quy tắc vòng tròn (Round-Robin) | E16: Phân tích yêu cầu nghiệp vụ, thiết kế bảng dữ liệu CSDL PostgreSQL, đặc tả API RESTful và luồng nghiệp vụ chi tiết cho: Chia đều khách hàng tiềm năng cho các cán bộ phụ trách không thiên vị | F16: /crm/lead-assignment | G16: Hệ Thống Tự Động | H16: Cao | I16: 0.5 | J16: 1.5 | K16: 0.5 | L16: =SUM(I16:K16) | M16: 100 | N16: Hoàn thành Dev | O16: Passed | P16: Đạt UAT | Q16: Round-Robin Dispatcher
... A104: WBS-CRM_LEAD-0600 | B104: CRM Quản Trị Khách Hàng, Lead & Trao Cơ Hội Referral | C104: Quản Lý Khách Hàng & Cơ Hội Giao Thương [Giai đoạn: Kiểm Thử Tự Động Toàn Diện E2E, Hiệu Năng & Nghiệm Thu UAT] | D104: [Kiểm Thử E2E & UAT] Báo cáo tỷ lệ chuyển đổi khách hàng qua từng giai đoạn (Conversion Rate) | E104: Kiểm thử hộp đen/hộp trắng toàn diện, kiểm tra tải đồng thời, đối soát dữ liệu và nghiệm thu Ban Lãnh Đạo: Biểu đồ phễu thu hẹp thể hiện tỷ lệ rơi rụng khách hàng qua các bước | F104: /crm/reports/funnel | G104: Ban Lãnh Đạo | H104: Cao | I104: 0.5 | J104: 0.5 | K104: 2 | L104: =SUM(I104:K104) | M104: 100 | N104: Hoàn thành Dev | O104: Passed | P104: Đạt UAT | Q104: Funnel Conversion BI
B105: TỔNG CỘNG PHÂN HỆ | I105: =SUM(I5:I104) | J105: =SUM(J5:J104) | K105: =SUM(K5:K104) | L105: =SUM(L5:L104) | M105: =AVERAGE(M5:M104)

Sheet WBS_07_EMAIL_TEMPLATES
A1: VIONE MASTER WBS: MẪU EMAIL, TRÌNH SOẠN THẢO & CHIẾN DỊCH TRUYỀN THÔNG
A3: Tài liệu phạm vi chi tiết PMO Enterprise: 100 tác vụ chuyên sâu • Cập nhật: 2026-09-13
